Workbook

Sheet data
AJ1: =DATE(2028,6,5)
C2: اطلاعات عمومی | F2: اطلاعات قبوض | L2: نامه ها
C4: عنوان مودی | F4: ردیف | G4: شماره قبض | H4: تاریخ صدور | I4: تاریخ وصول | J4: مبلغ قبض | L4: عنوان نامه | M4: شماره | N4: مورخ | O4: توضیحات | P4: مبلغ بدهی | Q4: سال
C5: شماره اقتصادی | F5: 1 | L5: برگ استرداد اصلی
C6: واحد مالیاتی | D6: 160300 | F6: 2 | L6: گزارش توجیه استرداد اداره
C7: استان | D7: خوزستان | F7: 3 | L7: تعهد اداره مالیاتی
C8: شهرستان | D8: اهواز | F8: 4 | L8: نامه ذیحسابی
C9: سال استرداد | F9: 5 | L9: وصول و اجرا | AJ9: عملکرد
C10: دوره | F10: 6 | L10: واحد مالیاتی تکلیفی | AJ10: ارزش افزوده
C11: منبع مالیاتی | F11: 7 | L11: درخواست استرداد مودی | AJ11: حقوق
C12: رئیس امور | D12: غلامرضا اسلامی | F12: 8
C13: رئیس گروه | D13: مسعود بصیر | F13: 9
C14: کارشناس ارشد | D14: مهدی دلفی | F14: 10
C15: بانک مودی | F15: 11 | L15: جمع
C16: شماره شبا | F16: 12
C17: نشانی مودی | F17: 13 | AI17: بله | AK17: قبول زیان
C18: علت استرداد | F18: =IF(TODAY()>=AJ1,"*فایل منقضی شد*","تعداد کل قبوض: "&COUNT(G5:G17)) | G18: جمع | J18: =IF(TODAY()>=AJ1,"*فایل منقضی شد*",SUM(J5:J17)) | AI18: خیر | AK18: معافیت مالیاتی
C19: شماره پرونده | AK19: رسیدگی به دفار
AK20: تایید اظهارنامه
AK21: علی الراس
C26: شرح مبالغ قابل استرداد | H26: مبلغ به ریال
C27: اصل مالیات | H27: =IF(TODAY()>=AJ1,"*فایل منقضی شد*",-E62-P15)
C28: حق تمبر
C29: سایر
C30: جرایم
C31: خسارت تاخیر در استرداد (تبصره ماده 243)
C32: جمع کل | H32: =IF(TODAY()>=AJ1,"*فایل منقضی شد*",SUM(H27:H31))
C34: مودی اظهار نامه تسلیم نموده؟
C36: شماره اظهارنامه
C38: تاریخ تسلیم اظهارنامه
C40: نحوه قطعی شدن پرونده
C42: شماره برگ قطعی
C44: تاریخ برگ قطعی
C46: درامد تشخیصی قبل از کسر مالیات
C48: جمع معافیتها و بخشودگی
C50: مانده مشمول | E50: =IF(TODAY()>=AJ1,"*فایل منقضی شد*",E46-E48)
C52: مالیات تشخیصی
C54: اضافه می گردد جرایم غیر قابل بخشش
C56: جمع | E56: =IF(TODAY()>=AJ1,"*فایل منقضی شد*",E52+E54)
C58: کسر می شود جایزه خوش حسابی
...

Sheet cheklist
B2: چك ليست كنترل اسناد استردادي اداره كل امورمالياتي
C3: رديف | D3: شرح | R3: رعايت | S3: عدم رعايت
B5: نامه استرداد | C5: 1 | D5: ثبت شماره دبير خانه وتاريخ مندرج در برگ استرداد درنامه مدير كل(نامه استرداد)
C6: 2 | D6: ثبت مبلغ بدهي مالياتي (( تكليفي موضوع ماده 104 ق.م.م ، حقوق ، ماليات و عوارض ارزش افزوده مودي در نامه مدير كل ودرج شماره حساب مربوطه))
B8: برگ استرداد | C8: 3 | D8: درج منبع مالياتي درفرم استرداد مالياتي (باتوجه به منابع مندرج درقبوض مالياتي)
C9: 4 | D9: تعیین جمع ماليات پرداختي مودي دربرگ استرداد مالياتي(با توجه به فرم تسهيم وسهم هر شهرستان)
C10: 5 | D10: درج قبوض ماليات پرداختي مودي كه ريز آن در جدول ( الف ) مي باشد
D11: ثبت شماره وتاريخ گزارش استرداد دربرگ استرداد
D12: درج مبلغ به حروف دربرگ استرداد
C13: 6 | D13: عدم استفاده از لاك غلط گير و مخدوش بودن سند استرداد
C14: 7 | D14: درج جمع قبوض ماليات پرداختي مودي دربرگ استرداد مالياتي جدول( ب)
C15: 8 | D15: مشخص كردن قبوض مالياتي كه جهت استرداد باطل مي گردد درجدول ( الف )
B17: گزارش استرداد | C17: 9 | D17: تعیین وضعيت بدهي مودي مالياتي درقسمت مربوط به اداره وصول واجرادرفرم گزارش استرداد
C18: الف ) | D18: مهر وامضاء نمودن توسط کارشناس ارشد مربوطه اداره وصول واجرا
C19: ب ) | D19: درصورت تائيد توسط كارشناس ارشدمالياتي به شيوه زير اقدام فرمايند:
C20: (ب-1 ) | D20: دريافت گواهي وضعيت مودي مالياتي ازسيستم اتوماسيون وصول واجرا كه درآن مشخصات مودي مالياتي ثبت گرديده وتائيد آن توسط كارشناس ارشد مالياتي مربوطه
C21: (ب -2) | D21: درج جمله: (گواهي اتوماسيون اداره وصول واجرا ضميمه مي باشد ) در فرم گزارش استرداد درقسمت وصول واجرا وتائيد آن توسط كارشناس ارشدمالياتي مربوطه
C22: 10 | D22: درج سال عملكرد تحت رسيدگي دركليه قسمتهاي فرم گزارش استرداد
C23: 11 | D23: تفكيك بدهي ماليات وعوارض ارزش افزوده ((مشخص بودن ميزان كسر هر آيتم از مبلغ استردادي درصورت داشتن بدهي مودي))
B25: ضمائم | C25: 12 | D25: ضميمه بودن اصل قبوض ماليات پرداختي در حد مورد نياز جهت استرداد
C26: 12-1 | D26: درصورت مفقود ي قبوض ماليات :
C27: الف) | D27: تعهد نامه ازمسئولين مالياتي در صورت مفقودي نسخه پرونده مالياتي
C28: ب) | D28: اقرار نامه ثبتي از مودي مالياتي درصورت مفقودي نسخه مودي مالياتي
C29: 12 | D29: نامه درخواست استرداد ، اعلام شماره حساب بانكي افراد حقيقي وحقوقي (بامهر شركت) ، معرفي نماينده وهمچنين درصورت تهاترساير بدهي هابا مبلغ استرداد از مودي ضميمه گردد
E32: =" رئیس گروه مالیاتی شهرستان "&data!D8&CHAR(10)&data!D13 | N32: =" رئیس امور مالیاتی شهرستان "&data!D8&CHAR(10)&data!D12

Sheet form1
E2: جمهوری اسلامی ایران | H2: نامه ذیحسابی | L2: شماره | M2: =data!M8
E3: وزارت امور اقتصادی و دارایی | L3: تاریخ | M3: =data!N8
E4: سازمان امور مالیاتی کشور
D8: =CHAR(10)&CHAR(10)&" احتراما به پیوست یک فقره پرونده استرداد شماره "&data!M5&" مورخ "&data!N5&" مربوط به "&data!D4&" با شماره اقتصادی"&data!D5&" به مبلغ "&TEXT(data!H32,"#,##0")&" ریال مربوط به مالیات "&data!D11&" سال "&data!D9&" ارسال می گردد. مقتضی است دستور فرمایید ضمن بررسی و وفق مقررات نسبت به استرداد وجه فوق الذکر اقدام و کل مبلغ "& TEXT(data!H32,"#,##0")& " ریال طبق درخواست کتبی به حساب نامبرده به شماره شبا"&data!D16&" نزد بانک "& data!D15&" پرداخت گردد"

Sheet form2
D3: استعلام از حوزه های مختلف
D5: =CHAR(10)&CHAR(10)&" به: کلیه واحد های اداره امور مالیاتی شهرستان "&data!D8&CHAR(10)&CHAR(10)&CHAR(10)&" با سلام"&CHAR(10)&" احتراما، نظر به اینکه مودی "&data!D4&" با کد اقتصادی "&data!D5&" به نشانی "&data!D17&" در واحد مالیاتی "&data!D6&" درخواست استرداد نموده است، از این رو خواهشمند است ضمن بررسی سوابق نامبرده در آن حوزه مالیاتی مراتب بدهی و یا عدم بدهکاری مشارالیه را جهت اقدامات بعدی در ذیل همین نامه به این واحد مالیاتی اعلام فرمایید."&CHAR(10)&CHAR(10)&" 1- واحد ارث:"&CHAR(10)&CHAR(10)&CHAR(10)&" 2- واحد وصول و اجرا:"&CHAR(10)&CHAR(10)&CHAR(10)&" 3- واحد شرکت ها و حقوق"&CHAR(10)&CHAR(10)&CHAR(10)&" 4- واحد مشاغل:"&CHAR(10)&CHAR(10)&CHAR(10)&" 5- واحد ارزش افزوده:"
E42: =" کارشناس ارشد مالیاتی شهرستان "&data!D8&CHAR(10)&data!D14

Sheet form3
N4: شماره | O4: =data!M6
E5: ="گزارش استرداد اضافه مالیات "&data!D11&" سال "&data!D9&" مودی "&data!D4 | N5: تاریخ | O5: =data!N6
D8: عنوان مودی | G8: =data!D4
D9: شماره اقتصادی | G9: =data!D5
D10: عملکرد منتهی به: | G10: =data!D9
D11: نشانی قانونی شخص حقوقی/حقیقی: | G11: =data!D17
D13: =" 1- مودی به موجب نامه وارد به شماره "&data!M11& " مورخ "&data!N11& "که در دبیرخانه اداره امور مالیاتی "&data!D6&" ثبت گردیده است، درخواست استرداد اضافه پرداختی را نموده است."
D17: =IF(data!E34="بله"," 2- مودی اظهارنامه خود را با شماره "&data!E36&" مورخ "&data!E38&" تسلیم نموده است"," مودی هیچگونه اظهارنامه ای تسلیم ننموده است")
D20: =" 3- پس از رسیدگی به عمل آمده و به موجب "&IF(TODAY()>=data!AJ1,"*فایل منقضی شد*",data!E40)&" به شرح زیر قطعی شده است:"
D24: ="4- شماره برگ قطعی مالیاتی "&data!E42&" مورخ "&data!E44&" می باشد"&CHAR(10)&CHAR(10)&" درامد تشخیصی قطعی قبل از کسر مالیات مبلغ "&IF(TODAY()>=data!AJ1,"*فایل منقضی شد*",TEXT(data!E46,"#,##0"))&" ریال"&CHAR(10)&" کسر می گردد: معافیت ها و بخشودگی "&TEXT(data!E48,"#,##0")&CHAR(10)&" -------------------"&CHAR(10)&" مانده مشمول مالیات "&TEXT(data!E50,"#,##0")&CHAR(10)&" مالیات قطعی "&IF(TODAY()>=data!AJ1,"*فایل منقضی شد*",TEXT(data!E52,"#,##0"))&CHAR(10)&" اضافه می گردد: جرایم غیرقابل بخشش "&TEXT(data!E54,"#,##0")&CHAR(10)&" -------------------"&CHAR(10)&" جمع "&TEXT(data!E56,"#,##0")&CHAR(10)&" کسر می گردد:"&CHAR(10)&" جایزه خوش حسابی "&TEXT(data!E58,"#,##0")&CHAR(10)&" به شرح جدول الف "&TEXT(data!E60,"#,##0")&CHAR(10)&" -------------------"&CHAR(10)&" مازاد پرداختی "&TEXT(data!E62,"#,##0")
E49: =" کارشناس ارشد مالیاتی شهرستان "&data!D8&CHAR(10)&data!D14

Sheet form4
E2: =" ادامه گزارش استرداد اضافه مالیات "&data!D11&" سال "&data!D9&" مودی "&data!D4 | N2: شماره | O2: =data!M6
N3: تاریخ | O3: =data!N6
E6: با توجه به گزارش فوق، اضافه پرداختی مؤدی در عملکرد سال مورد گزارش بعد از کسر موارد زیر به وی قابل استرداد خواهد بود
E9: =" الف- با توجه به نامه شماره "&data!M9&" مورخ "&data!N9&" اداره وصول و اجرا، مودی "&data!O9&CHAR(10)&" مودی مبلغ "&TEXT(data!P9,"#,##0")&" ریال بابت مالیات و جرایم سنوات "&data!Q9&" دارد"
E13: =" ب- با توجه به نامه شماره "&data!M10&" مورخ "&data!N10&" واحد مالیات حقوق و تکلیفی، مودی "&data!O10&CHAR(10)&" مودی مبلغ "&TEXT(data!P10,"#,##0")&" ریال بابت مالیات و جرایم سنوات "&data!Q10&" دارد"
E17: =" ج- با توجه به نامه شماره "&data!M10&" مورخ "&data!N10&" واحد مالیات حقوق و تکلیفی، مودی "&data!O10&CHAR(10)&" مودی مبلغ "&TEXT(data!P10,"#,##0")&" ریال بابت مالیات و جرایم سنوات "&data!Q10&" دارد"
E21: =" پرداخت مانده اضافه پرداختی قابل پرداخت به مودی پس از کسر بدهی های موضوع الف و ب و ج فوق به مبلغ "&IF(TODAY()>=data!AJ1,"*فایل منقضی شد*",TEXT((-data!E62-data!P15),"#,##0"))&" مورد تایید است"&CHAR(10)&" مراتب جهت اظهار نظر رئیس گروه مالیاتی اعلام می گردد"
L27: =" کارشناس ارشد مالیاتی شهرستان "&data!D8&CHAR(10)&data!D14
E31: =" نظر رئیس گروه مالیاتی شهرستان "&data!D8
E33: =" رئیس محترم اداره مالیاتی شهرستان "&data!D8&CHAR(10)&" مضمون گزارش استرداد مالیات مربوط به عملکرد سال "&data!D9&" مودی "&data!D4&" تهیه شده توسط کارشناس ارشد واحد مالیاتی "&data!D6&" با تعیین و تایید مبلغ "&TEXT(-data!E62,"#,##0")&" ریال مالیات اضافه دریافتی قبل از کسر بدهی های مالیاتی دیگر و مبلغ "&TEXT((-data!E62-data!P15),"#,##0")&" ریال مانده اضافه دریافتی بعد از کسر بدهی های مالیاتی دیگر مورد تایید اینجانب است."&CHAR(10)&" جهت استحضار و تایید و صدور دستور لازم مبنی بر تهیه برگ استردا ایفاد می گردد"
L41: =" رئیس گروه مالیاتی شهرستان "&data!D8&CHAR(10)&data!D13
E43: =" نظر رئیس امور مالیاتی شهرستان "&data!D8
E45: =" رئیس گروه مالیاتی شهرستان "&data!D8&CHAR(10)&" گزارش استرداد مالیات اضافه دریافتی مربوط به عملکرد سال "&data!D9&" مودی "&data!D4&" با تعیین مبلغ "&TEXT(-data!E62,"#,##0")& " ریال مانده اضافه دریافتی قبل از کسر بدهی های مالیاتی دیگر و مبلغ "&TEXT((-data!E62-data!P15),"#,##0")& " ریال مانده اضافه دریافتی بعد از کسر بدهیهای مالیاتی دیگر که می بایست به مودی مسترد گردد، ملاحضه شد و مورد تایید است. لطفا دستور فرمایید اقدام به تهیه فرم استرداد مالیاتی بر اساس موازین قانونی دستورالعمل مربوط گردد."
L53: =" رئیس امور مالیاتی شهرستان "&data!D8&CHAR(10)&data!D12

Sheet form5
E6: جمهوری اسلامی ایران | H6: برگ استرداد مالیات اضافه دریافتی | L6: شماره: | M6: =data!M5
E7: وزرات امور اقتصاد و دارایی | L7: تاریخ | M7: =data!N5
E8: سازمان امور مالیاتی کشور | L8: شماره پرونده | M8: =data!D19
E10: سازمان امور مالیاتی کشور- موضوع ماده 242 اصلاحی قانونی مالاتی های مستقیم مصوب 1380/11/27
D12: مودی: | F12: =data!D4 | I12: شماره اقتصادی: | K12: =data!D5
D13: نشانی: | F13: =data!D17
D14: منبع مالیاتی: | G14: =data!D11 | H14: عملکرد سال: | I14: =data!D9 | J14: دوره: | K14: =data!D10
D16: =" مبلغ"&TEXT(data!J18,"#,##0")&" ریال به موجب "&data!F18&" فقره رسید مالیاتی به شرح ذیل به شرح جدول الف "
E17: شماره قبض | F17: تاریخ صدور | G17: نام شعبه | H17: شهرستان | I17: مبلغ مندرج در قبض | J17: شماره ردیف دفتر درامد | K17: ملاحضات
E18: جدول الف | F18: جدول الف | H18: =data!D8 | I18: =data!J18
D19: =" پرداخت نموده اند که به موجب گزارش رسیدگی شماره "&data!M6& "مورخ"&data!N6&" اداره امور مالیاتی و رای هیات حل اختلاف مالیاتی مبلغ مالیات پرداختی به شرح زیر و به علت "&data!D18&" قابل استرداد تشخیص گردیده است"
E24: شرح مبالغ قابل استرداد | J24: مبلغ به ریال
E25: اصل مالیات | J25: =data!H27
E26: حق تمبر | J26: =data!H28
E27: سایر | J27: =data!H30
E28: جرایم | J28: =data!#REF!
E29: خسارت تاخیر در استرداد (تبصره ماده 243) | J29: =data!H31
E30: جمع کل | J30: =data!H32
D31: ="در اجرای مفاد ماده 242 قانون مالیات مستقیم به شرح ذیل مقرر می گردد:"&CHAR(10)&data!D18&" قابل استرداد تشخیص گردیده است علیهذا خواشمند است در اجرای ماده 242 اصلاحی قانون مالیات های مستقیم مصوب 1380/11/27 مبلغ "&TEXT(J30,"#,##0")&" ریال اضافه دریافتی و خسارت تاخیر را از محل وصولی جاری ظرف یک ماه برگشت و به ذینفع پرداخت و نسخه ای از سند پرداخت را جهت ضبط در پرونده مالیات بر عملکرد امور مالیاتی شهرستان "&data!D8&" ارسال نمایید"
E40: =" رسید بانکی"&"/"&" رسید های بانکی پرداخت مالیات که برای اصلاح یا ابطال به ضمیمه ایفاد می گردد، به شرح زیر است:"
E42: شماره قبض | F42: تاریخ صدور | G42: نام شعبه | H42: شهرستان | I42: مبلغ مندرج در قبض | J42: شماره ردیف دفتر درامد | K42: مبلغ قابل استرداد
E43: جدول الف | F43: جدول الف | G43: جدول الف | I43: جدول الف | K43: جدول الف
E45: مهر و امضا | J45: مهر و امضا
E46: =" رئیس گروه مالیاتی "&data!D6&" شهرستان "&data!D8 | J46: =" رئیس امور مالیاتی "&data!D6&" شهرستان "&data!D8
E47: =data!D13 | J47: =data!D12

Sheet form6
L4: شماره | M4: =data!M7
L5: تاریخ | M5: =data!N7
G6: فرم تعهد اداره امور مالیاتی
D8: =CHAR(10)&CHAR(10)&" اینجانب "&data!D14&" کارشناس ارشد مالیاتی اداره امور مالیاتی "&data!D6&" شهرستان "&data!D8&" بدینوسیله متعهد می گردم که قبوض به شرح جدول الف(ضمیمه) سال"&data!D9&" مربوط به مودی "&data!D4&" قبلا لحاظ یا مسترد نشده است و چنانچه قبض مذکور در سال های یاد شده از سوی اینجانب مورد سوء استفاده قرار گیرد و از این جهت ضرر و زیانی متوجه دولت شود، کلیه خسارات وارده را جبران نمایم."&CHAR(10)&CHAR(10)&"حسابرس ارشد مالیاتی "&data!D6&" شهرستان "&data!D8&" رئیس گروه مالیاتی "&data!D6&" شهرستان "&data!D8
F21: =data!D14 | K21: =data!D13
G25: =CHAR(10)&CHAR(10)&CHAR(10)&" رئیس امور مالیاتی "&data!D6&" شهرستان "&data!D8
H28: =data!D12

Sheet form7
D3: جمهوری اسلامی ایران | E3: جدول( الف) برگ استرداد موضوع ماده 242 ق0م0م | J3: شماره | K3: =data!M5
D4: وزارت امور اقتصادی و دارایی | J4: تاریخ | K4: =data!N5
D5: سازمان امور مالیاتی
D6: =data!F4 | E6: =data!G4 | F6: =data!H4 | G6: نام شعبه | H6: شهرستان | I6: مبلغ مندرج در رسید | J6: شماره درامد
D7: =data!F5 | E7: =data!G5 | F7: =data!H5 | I7: =data!J5
D8: =data!F6 | E8: =data!G6 | F8: =data!H6 | I8: =data!J6
D9: =data!F7 | E9: =data!G7 | I9: =data!J7
D10: =data!F8 | E10: =data!G8 | I10: =data!J8
D11: =data!F9 | E11: =data!G9 | I11: =data!J9
D12: =data!F10 | E12: =data!G10 | I12: =data!J10
D13: =data!F11 | E13: =data!G11 | I13: =data!J11
D14: =data!F12 | E14: =data!G12 | I14: =data!J12
D15: =data!F13 | E15: =data!G13 | I15: =data!J13
D16: =data!F14 | E16: =data!G14 | I16: =data!J14
D17: =data!F15 | E17: =data!G15 | I17: =data!J15
D18: =data!F16 | E18: =data!G16 | I18: =data!J16
D19: =data!F17 | E19: =data!G17 | I19: =data!J17
D20: =data!F18 | E20: =data!G18
C22: =" رئیس گروه مالیاتی شهرستان "&data!D8&CHAR(10)&data!D13 | H22: =" رئیس امور مالیاتی شهرستان "&data!D8&CHAR(10)&data!D12
